Workbook

Sheet Lab Test Data Grids
A1: PV LAB EXPERIMENTAL DATA ENTRY TEMPLATE (DDM PARAMETER EXTRACTION)Day3-21August 2026 | N1: excellent ST < 1.5 , acceptable 1.5<ST<3, poor ST>3
N2: Basic uniformity <10
A3: 20260819-E01 – Temperaturw Grid (°C) | I3: 20260819-E01 – Irradiance Grid (W/m²) | R3: 20260819-E01 – Temperature Grid After sweep (°C)
A4: Position | B4: Left | C4: Centre | D4: Right | F4: Metric | I4: Position | J4: Left | K4: Centre | L4: Right | N4: Metric | R4: Position | S4: Left | T4: Centre | U4: Right | W4: Metric
A5: Top | B5: 29.6 | C5: 30.4 | D5: 30.5 | F5: Average | G5: =AVERAGE(B5:D7) -> 31.888889 | I5: Top | J5: 362 | K5: 383 | L5: 345 | N5: Average | O5: =AVERAGE(J5:L7) -> 384.22222 | R5: Top | S5: 33.7 | T5: 33.3 | U5: 33 | W5: Average | X5: =AVERAGE(S5:U7) -> 34.655556
A6: Middle | B6: 31.4 | C6: 32.2 | D6: 32.1 | F6: Minimum | G6: =MIN(B5:D7) -> 29.6 | I6: Middle | J6: 420 | K6: 427 | L6: 396 | N6: Minimum | O6: =MIN(J5:L7) -> 345 | R6: Middle | S6: 34 | T6: 33.7 | U6: 34.4 | W6: Minimum | X6: =MIN(S5:U7) -> 33
A7: Bottom | B7: 33.4 | C7: 34.4 | D7: 33 | F7: Maximum | G7: =MAX(B5:D7) -> 34.4 | I7: Bottom | J7: 377 | K7: 391 | L7: 357 | N7: Maximum | O7: =MAX(J5:L7) -> 427 | R7: Bottom | S7: 36.4 | T7: 36.7 | U7: 36.7 | W7: Maximum | X7: =MAX(S5:U7) -> 36.7
F8: Range | G8: =G7-G6 -> 4.8 | N8: Range | O8: =O7-O6 -> 82 | W8: Range | X8: =X7-X6 -> 3.7
A9: ENVIRONMENTAL & TEST CONDITIONS: | F9: Std | G9: =_xlfn.STDEV.S(B5:D7) -> 1.5648039 | N9: Uniform(%) | O9: =((MAX(J5:L7)-MIN(J5:L7))/(MAX(J5:L7)+MIN(J5:L7)))*100 -> 10.621762 | W9: Std | X9: =_xlfn.STDEV.S(S5:U7) -> 1.5125402
A10: Lamp Distance (cm): | C10: 90 cm
A11: Fan Condition: | C11: on
A12: Window Condition: | C12: Closed / unShielded
A13: Test Purpose / Notes: | C13: low irradiance constant temperature(AIM g=400, T= 25 )
A16: 20260819-E02 – Temperature Grid (°C) | I16: 20260819-E02 – Irradiance Grid (W/m²) | Q16: 20260819-E02 – Temperature Grid After(°C)
A17: Position | B17: Left | C17: Centre | D17: Right | F17: Metric | I17: Position | J17: Left | K17: Centre | L17: Right | N17: Metric | Q17: Position | R17: Left | S17: Centre | T17: Right | V17: Metric
A18: Top | B18: 31.3 | C18: 31.3 | D18: 31.9 | F18: Average | G18: =AVERAGE(B18:D20) -> 33.877778 | I18: Top | J18: 374 | K18: 393 | L18: 355 | N18: Average | O18: =AVERAGE(J18:L20) -> 392.11111 | Q18: Top | R18: 35.3 | S18: 35.2 | T18: 34.8 | V18: Average | W18: =AVERAGE(R18:T20) -> 36.744444
A19: Middle | B19: 33.4 | C19: 35.4 | D19: 33.9 | F19: Minimum | G19: =MIN(B18:D20) -> 31.3 | I19: Middle | J19: 416 | K19: 445 | L19: 396 | N19: Minimum | O19: =MIN(J18:L20) -> 355 | Q19: Middle | R19: 35.9 | S19: 37.2 | T19: 36.2 | V19: Minimum | W19: =MIN(R18:T20) -> 34.8
A20: Bottom | B20: 35.6 | C20: 36.6 | D20: 35.5 | F20: Maximum | G20: =MAX(B18:D20) -> 36.6 | I20: Bottom | J20: 378 | K20: 402 | L20: 370 | N20: Maximum | O20: =MAX(J18:L20) -> 445 | Q20: Bottom | R20: 38.1 | S20: 39.5 | T20: 38.5 | V20: Maximum | W20: =MAX(R18:T20) -> 39.5
F21: Range | G21: =G20-G19 -> 5.3 | N21: Range | O21: =O20-O19 -> 90 | V21: Range | W21: =W20-W19 -> 4.7
A22: ENVIRONMENTAL & TEST CONDITIONS: | F22: Std | G22: =_xlfn.STDEV.S(B18:D20) -> 2.0234734 | N22: Uniform(%) | O22: =((MAX(J18:L20)-MIN(J18:L20))/(MAX(J18:L20)+MIN(J18:L20)))*100 -> 11.25 | V22: Std | W22: =_xlfn.STDEV.S(R18:T20) -> 1.6576422
A23: Lamp Distance (cm): | C23: 90 cm
A24: Fan Condition: | C24: ON
A25: Window Condition: | C25: Closed / unShielded
A26: Test Purpose / Notes: | C26: constant temperature
A29: 20260819-E03 – Temperature Grid (°C) | I29: 20260819-E03 – Irradiance Grid (W/m²) | Q29: 20260819-E02 – Temperature Grid After(°C)
A30: Position | B30: Left | C30: Centre | D30: Right | F30: Metric | I30: Position | J30: Left | K30: Centre | L30: Right | N30: Metric | Q30: Position | R30: Left | S30: Centre | T30: Right | V30: Metric
A31: Top | B31: 28.1 | C31: 28.6 | D31: 28.5 | F31: Average | G31: =AVERAGE(B31:D33) -> 30.888889 | I31: Top | J31: 824 | K31: 910 | L31: 821 | N31: Average | O31: =AVERAGE(J31:L33) -> 861.88889 | Q31: Top | R31: 36.6 | S31: 36.3 | T31: 36 | V31: Average | W31: =AVERAGE(R31:T33) -> 38
A32: Middle | B32: 30.5 | C32: 31.4 | D32: 31 | F32: Minimum | G32: =MIN(B31:D33) -> 28.1 | I32: Middle | J32: 870 | K32: 990 | L32: 823 | N32: Minimum | O32: =MIN(J31:L33) -> 821 | Q32: Middle | R32: 38.3 | S32: 38.4 | T32: 37.5 | V32: Minimum | W32: =MIN(R31:T33) -> 36
A33: Bottom | B33: 33.2 | C33: 33.5 | D33: 33.2 | F33: Maximum | G33: =MAX(B31:D33) -> 33.5 | I33: Bottom | J33: 822 | K33: 822 | L33: 875 | N33: Maximum | O33: =MAX(J31:L33) -> 990 | Q33: Bottom | R33: 39.7 | S33: 41.2 | V33: Maximum | W33: =MAX(R31:T33) -> 41.2
F34: Range | G34: =G33-G32 -> 5.4 | N34: Range | O34: =O33-O32 -> 169 | V34: Range | W34: =W33-W32 -> 5.2
A35: ENVIRONMENTAL & TEST CONDITIONS: | F35: Std | G35: =_xlfn.STDEV.S(B31:D33) -> 2.140353 | N35: Uniform(%) | O35: =((MAX(J31:L33)-MIN(J31:L33))/(MAX(J31:L33)+MIN(J31:L33)))*100 -> 9.3318609 | V35: Std | W35: =_xlfn.STDEV.S(R31:T33) -> 1.7920459
A36: Lamp Distance (cm): | C36: 57 cm
A37: Fan Condition: | C37: ON (High Speed - 3)
A38: Window Condition: | C38: Closed / unShielded
A39: Test Purpose / Notes: | C39: constant temperature
A44: 20260819-E03 – Temperature Grid (°C) | I44: 20260819-E03 – Irradiance Grid (W/m²) | Q44: 20260819-E02 – Temperature Grid After(°C)
A45: Position | B45: Left | C45: Centre | D45: Right | F45: Metric | I45: Position | J45: Left | K45: Centre | L45: Right | N45: Metric | Q45: Position | R45: Left | S45: Centre | T45: Right | V45: Metric
A46: Top | B46: 31.5 | C46: 32.2 | D46: 32 | F46: Average | G46: =AVERAGE(B46:D48) -> 35.077778 | I46: Top | J46: 520 | K46: 550 | L46: 510 | N46: Average | O46: =AVERAGE(J46:L48) -> 573.88889 | Q46: Top | R46: 35.3 | S46: 35.2 | T46: 34.8 | V46: Average | W46: =AVERAGE(R46:T48) -> 36.744444
A47: Middle | B47: 36.8 | C47: 36.7 | D47: 35.4 | F47: Minimum | G47: =MIN(B46:D48) -> 31.5 | I47: Middle | J47: 610 | K47: 640 | L47: 590 | N47: Minimum | O47: =MIN(J46:L48) -> 510 | Q47: Middle | R47: 35.9 | S47: 37.2 | T47: 36.2 | V47: Minimum | W47: =MIN(R46:T48) -> 34.8
A48: Bottom | B48: 35.1 | C48: 37.8 | D48: 38.2 | F48: Maximum | G48: =MAX(B46:D48) -> 38.2 | I48: Bottom | J48: 580 | K48: 605 | L48: 560 | N48: Maximum | O48: =MAX(J46:L48) -> 640 | Q48: Bottom | R48: 38.1 | S48: 39.5 | T48: 38.5 | V48: Maximum | W48: =MAX(R46:T48) -> 39.5
...

Sheet Master Raw Data Log
A1: MASTER EXPERIMENTAL LOG & MEASURED DATA (FOR CLSHADE / MATLAB IMPORT)
A3: Run ID | B3: Date | C3: Lamp Distance (cm) | D3: Fan Speed | E3: Window Status | F3: Avg Temp (°C) | G3: Temp Range (°C) | H3: Avg Irradiance (W/m²) | I3: Irradiance Range (W/m²) | J3: I-V Sweep File Ref | K3: Notes / Target Parameter
A4: 20260819-E01 | B4: 2026-08-19 | C4: 90 | D4: OFF | E4: Closed | F4: ='Lab Test Data Grids'!G5 -> 31.888889 | G4: ='Lab Test Data Grids'!G8 -> 4.8 | H4: ='Lab Test Data Grids'!O5 -> 384.22222 | I4: ='Lab Test Data Grids'!O8 -> 82 | J4: IV_sweep_E01.csv | K4: Rsh extraction focus
A5: 20260819-E02 | B5: 2026-08-19 | C5: 60 | D5: Low | E5: Closed | F5: ='Lab Test Data Grids'!G18 -> 33.877778 | G5: ='Lab Test Data Grids'!G21 -> 5.3 | H5: ='Lab Test Data Grids'!O18 -> 392.11111 | I5: ='Lab Test Data Grids'!O21 -> 90 | J5: IV_sweep_E02.csv | K5: Thermal drift monitoring
A6: 20260819-E03 | B6: 2026-08-19 | C6: 40 | D6: High | E6: Closed | F6: ='Lab Test Data Grids'!G31 -> 30.888889 | G6: ='Lab Test Data Grids'!G34 -> 5.4 | H6: ='Lab Test Data Grids'!O31 -> 861.88889 | I6: ='Lab Test Data Grids'!O34 -> 169 | J6: IV_sweep_E03.csv | K6: Iph & Rs isolation at 25°C

Sheet Sheet1
A1: PV LAB EXPERIMENTAL DATA ENTRY TEMPLATE (DDM PARAMETER EXTRACTION)Day4-24August 2026
A3: 20260819-E02 – Temperature Grid (°C) | I3: 20260819-E02 – Irradiance Grid (W/m²) | Q3: 20260819-E02 – Temperature Grid After(°C)
A4: Position | B4: Left | C4: Centre | D4: Right | F4: Metric | I4: Position | J4: Left | K4: Centre | L4: Right | N4: Metric | Q4: Position | R4: Left | S4: Centre | T4: Right | V4: Metric
A5: Top | B5: 31.5 | C5: 30.8 | D5: 30.2 | F5: Average | G5: =AVERAGE(B5:D7) -> 33.522222 | I5: Top | J5: 826 | K5: 934 | L5: 826 | N5: Average | O5: =AVERAGE(J5:L7) -> 887.44444 | Q5: Top | R5: 40.4 | S5: 38.7 | T5: 37 | V5: Average | W5: =AVERAGE(R5:T7) -> 40.277778
A6: Middle | B6: 33.2 | C6: 33.5 | D6: 32.3 | F6: Minimum | G6: =MIN(B5:D7) -> 30.2 | I6: Middle | J6: 874 | K6: 1003 | L6: 872 | N6: Minimum | O6: =MIN(J5:L7) -> 826 | Q6: Middle | R6: 41 | S6: 40.9 | T6: 37.4 | V6: Minimum | W6: =MIN(R5:T7) -> 37
A7: Bottom | B7: 36.1 | C7: 38 | D7: 36.1 | F7: Maximum | G7: =MAX(B5:D7) -> 38 | I7: Bottom | J7: 852 | K7: 960 | L7: 840 | N7: Maximum | O7: =MAX(J5:L7) -> 1003 | Q7: Bottom | R7: 42.9 | S7: 42.9 | T7: 41.3 | V7: Maximum | W7: =MAX(R5:T7) -> 42.9
F8: Range | G8: =G7-G6 -> 7.8 | N8: Range | O8: =O7-O6 -> 177 | V8: Range | W8: =W7-W6 -> 5.9
A9: ENVIRONMENTAL & TEST CONDITIONS: | F9: Std | G9: =_xlfn.STDEV.S(B5:D7) -> 2.6803814 | N9: Uniform(%) | O9: =((MAX(J5:L7)-MIN(J5:L7))/(MAX(J5:L7)+MIN(J5:L7)))*100 -> 9.6774194 | V9: Std | W9: =_xlfn.STDEV.S(R5:T7) -> 2.1574162
A10: Lamp Distance (cm): | C10: 60 cm
A11: Fan Condition: | C11: ON
A12: Window Condition: | C12: Closed / unShielded
A13: Test Purpose / Notes: | C13: At STC condtions (1000 W/m² at 25°C )
A19: 20260819-E02 – Temperature Grid (°C) | I19: 20260819-E02 – Irradiance Grid (W/m²) | Q19: 20260819-E02 – Temperature Grid After(°C)
A20: Position | B20: Left | C20: Centre | D20: Right | F20: Metric | I20: Position | J20: Left | K20: Centre | L20: Right | N20: Metric | Q20: Position | R20: Left | S20: Centre | T20: Right | V20: Metric
A21: Top | B21: 27.7 | C21: 26.9 | D21: 27 | F21: Average | G21: =AVERAGE(B21:D23) -> 28.477778 | I21: Top | J21: 285 | K21: 262 | L21: 256 | N21: Average | O21: =AVERAGE(J21:L23) -> 292.33333 | Q21: Top | R21: 30.4 | S21: 30.2 | T21: 29.9 | V21: Average | W21: =AVERAGE(R21:T23) -> 31.225
A22: Middle | B22: 28.7 | C22: 29.2 | D22: 28.3 | F22: Minimum | G22: =MIN(B21:D23) -> 26.9 | I22: Middle | J22: 301 | K22: 303 | L22: 284 | N22: Minimum | O22: =MIN(J21:L23) -> 256 | Q22: Middle | R22: 31.6 | S22: 31..3 | T22: 30.9 | V22: Minimum | W22: =MIN(R21:T23) -> 29.9
A23: Bottom | B23: 29.4 | C23: 29.5 | D23: 29.6 | F23: Maximum | G23: =MAX(B21:D23) -> 29.6 | I23: Bottom | J23: 315 | K23: 324 | L23: 301 | N23: Maximum | O23: =MAX(J21:L23) -> 324 | Q23: Bottom | R23: 32.1 | S23: 32.6 | T23: 32.1 | V23: Maximum | W23: =MAX(R21:T23) -> 32.6
F24: Range | G24: =G23-G22 -> 2.7 | N24: Range | O24: =O23-O22 -> 68 | V24: Range | W24: =W23-W22 -> 2.7
A25: ENVIRONMENTAL & TEST CONDITIONS: | F25: Std | G25: =_xlfn.STDEV.S(B21:D23) -> 1.0627532 | N25: Uniform(%) | O25: =((MAX(J21:L23)-MIN(J21:L23))/(MAX(J21:L23)+MIN(J21:L23)))*100 -> 11.724138 | V25: Std | W25: =_xlfn.STDEV.S(R21:T23) -> 1.0110108
A26: Lamp Distance (cm): | C26: 60 cm
A27: Fan Condition: | C27: ON
A28: Window Condition: | C28: Closed / unShielded
A29: Test Purpose / Notes: | C29: At low irradiance

Sheet Env 01 Sep 2026
A1: PV LAB EXPERIMENTAL DATA ENTRY TEMPLATE (DDM PARAMETER EXTRACTION)--- 01 September 2026
A3: 20260819-E02 – Temperature Grid (°C) | I3: 20260819-E02 – Irradiance Grid (W/m²) | Q3: 20260819-E02 – Temperature Grid After(°C)
A4: Position | B4: Left | C4: Centre | D4: Right | F4: Metric | I4: Position | J4: Left | K4: Centre | L4: Right | N4: Metric | Q4: Position | R4: Left | S4: Centre | T4: Right | V4: Metric
A5: Top | B5: 32.3 | C5: 31.2 | D5: 32 | F5: Average | G5: =AVERAGE(B5:D7) -> 32.388889 | I5: Top | J5: 153 | K5: 165 | L5: 151 | N5: Average | O5: =AVERAGE(J5:L7) -> 167.11111 | Q5: Top | R5: 32.1 | S5: 32.5 | T5: 33.5 | V5: Average | W5: =AVERAGE(R5:T7) -> 33.1
A6: Middle | B6: 30.4 | C6: 31.7 | D6: 33.1 | F6: Minimum | G6: =MIN(B5:D7) -> 30.4 | I6: Middle | J6: 177 | K6: 186 | L6: 170 | N6: Minimum | O6: =MIN(J5:L7) -> 151 | Q6: Middle | R6: 31.5 | S6: 32.5 | T6: 32.4 | V6: Minimum | W6: =MIN(R5:T7) -> 31.5
A7: Bottom | B7: 33.4 | C7: 34.1 | D7: 33.3 | F7: Maximum | G7: =MAX(B5:D7) -> 34.1 | I7: Bottom | J7: 168 | K7: 175 | L7: 159 | N7: Maximum | O7: =MAX(J5:L7) -> 186 | Q7: Bottom | R7: 34.1 | S7: 34.8 | T7: 34.5 | V7: Maximum | W7: =MAX(R5:T7) -> 34.8
F8: Range | G8: =G7-G6 -> 3.7 | N8: Range | O8: =O7-O6 -> 35 | V8: Range | W8: =W7-W6 -> 3.3
A9: ENVIRONMENTAL & TEST CONDITIONS: | F9: Std | G9: =_xlfn.STDEV.S(B5:D7) -> 1.187902 | N9: Uniform(%) | O9: =((MAX(J5:L7)-MIN(J5:L7))/(MAX(J5:L7)+MIN(J5:L7)))*100 -> 10.385757 | V9: Std | W9: =_xlfn.STDEV.S(R5:T7) -> 1.1608187
A10: Lamp Distance (cm): | C10: 90 cm, voltage bulbs at 150V
A11: Fan Condition: | C11: ON
A12: Window Condition: | C12: Closed / unShielded
A13: Test Purpose / Notes: | C13: constant temperature varying irradance(lowest irradiance)
A18: 20260819-E02 – Temperature Grid (°C) | I18: 20260819-E02 – Irradiance Grid (W/m²) | Q18: 20260819-E02 – Temperature Grid After(°C)
A19: Position | B19: Left | C19: Centre | D19: Right | F19: Metric | I19: Position | J19: Left | K19: Centre | L19: Right | N19: Metric | Q19: Position | R19: Left | S19: Centre | T19: Right | V19: Metric
A20: Top | B20: 32.5 | C20: 32.7 | D20: 33.6 | F20: Average | G20: =AVERAGE(B20:D22) -> 34.677778 | I20: Top | J20: 300 | K20: 320 | L20: 280 | N20: Average | O20: =AVERAGE(J20:L22) -> 308.22222 | Q20: Top | R20: 33.4 | S20: 34.3 | T20: 35.4 | V20: Average | W20: =AVERAGE(R20:T22) -> 36.366667
A21: Middle | B21: 34.6 | C21: 35.8 | D21: 34.6 | F21: Minimum | G21: =MIN(B20:D22) -> 32.5 | I21: Middle | J21: 330 | K21: 340 | L21: 297 | N21: Minimum | O21: =MIN(J20:L22) -> 270 | Q21: Middle | R21: 35.6 | S21: 36.6 | T21: 37.1 | V21: Minimum | W21: =MIN(R20:T22) -> 33.4
A22: Bottom | B22: 35.8 | C22: 36.5 | D22: 36 | F22: Maximum | G22: =MAX(B20:D22) -> 36.5 | I22: Bottom | J22: 317 | K22: 320 | L22: 270 | N22: Maximum | O22: =MAX(J20:L22) -> 340 | Q22: Bottom | R22: 38.1 | S22: 38.3 | T22: 38.5 | V22: Maximum | W22: =MAX(R20:T22) -> 38.5
F23: Range | G23: =G22-G21 -> 4 | N23: Range | O23: =O22-O21 -> 70 | V23: Range | W23: =W22-W21 -> 5.1
A24: ENVIRONMENTAL & TEST CONDITIONS: | F24: Std | G24: =_xlfn.STDEV.S(B20:D22) -> 1.4754472 | N24: Uniform(%) | O24: =((MAX(J20:L22)-MIN(J20:L22))/(MAX(J20:L22)+MIN(J20:L22)))*100 -> 11.47541 | V24: Std | W24: =_xlfn.STDEV.S(R20:T22) -> 1.8193405
A25: Lamp Distance (cm): | C25: 90 cm voltage bulbs at 200V
A26: Fan Condition: | C26: ON
A27: Window Condition: | C27: Closed / unShielded
A28: Test Purpose / Notes: | C28: constant temperature varying irradance(mid irradiance)
A36: 20260819-E02 – Temperature Grid (°C) | I36: 20260819-E02 – Irradiance Grid (W/m²) | Q36: 20260819-E02 – Temperature Grid After(°C)
A37: Position | B37: Left | C37: Centre | D37: Right | F37: Metric | I37: Position | J37: Left | K37: Centre | L37: Right | N37: Metric | Q37: Position | R37: Left | S37: Centre | T37: Right | V37: Metric
A38: Top | B38: 31.3 | C38: 31 | D38: 33.1 | F38: Average | G38: =AVERAGE(B38:D40) -> 34.522222 | I38: Top | J38: 460 | K38: 496 | L38: 407 | N38: Average | O38: =AVERAGE(J38:L40) -> 445.55556 | Q38: Top | R38: 36.2 | S38: 35 | T38: 37.2 | V38: Average | W38: =AVERAGE(R38:T40) -> 37.433333
A39: Middle | B39: 33.4 | C39: 35.2 | D39: 35.7 | F39: Minimum | G39: =MIN(B38:D40) -> 31 | I39: Middle | J39: 482 | K39: 490 | L39: 415 | N39: Minimum | O39: =MIN(J38:L40) -> 407 | Q39: Middle | R39: 36.7 | S39: 37.5 | T39: 37.9 | V39: Minimum | W39: =MIN(R38:T40) -> 35
A40: Bottom | B40: 36.5 | C40: 36.9 | D40: 37.6 | F40: Maximum | G40: =MAX(B38:D40) -> 37.6 | I40: Bottom | J40: 412 | K40: 440 | L40: 408 | N40: Maximum | O40: =MAX(J38:L40) -> 496 | Q40: Bottom | R40: 38.4 | S40: 39.5 | T40: 38.5 | V40: Maximum | W40: =MAX(R38:T40) -> 39.5
F41: Range | G41: =G40-G39 -> 6.6 | N41: Range | O41: =O40-O39 -> 89 | V41: Range | W41: =W40-W39 -> 4.5
A42: ENVIRONMENTAL & TEST CONDITIONS: | F42: Std | G42: =_xlfn.STDEV.S(B38:D40) -> 2.4226936 | N42: Uniform(%) | O42: =((MAX(J38:L40)-MIN(J38:L40))/(MAX(J38:L40)+MIN(J38:L40)))*100 -> 9.8560354 | V42: Std | W42: =_xlfn.STDEV.S(R38:T40) -> 1.3509256
A43: Lamp Distance (cm): | C43: 90 cm voltage bulbs at 250V
A44: Fan Condition: | C44: ON
A45: Window Condition: | C45: Closed / unShielded
A46: Test Purpose / Notes: | C46: constant temperature varying irradance(highest irradiance)
A52: 20260819-E02 – Temperature Grid (°C) | I52: 20260819-E02 – Irradiance Grid (W/m²) | Q52: 20260819-E02 – Temperature Grid After(°C)
A53: Position | B53: Left | C53: Centre | D53: Right | F53: Metric | I53: Position | J53: Left | K53: Centre | L53: Right | N53: Metric | Q53: Position | R53: Left | S53: Centre | T53: Right | V53: Metric
A54: Top | F54: Average | G54: #DIV/0! | I54: Top | N54: Average | O54: #DIV/0! | Q54: Top | V54: Average | W54: #DIV/0!
A55: Middle | F55: Minimum | G55: 0 | I55: Middle | N55: Minimum | O55: 0 | Q55: Middle | V55: Minimum | W55: 0
A56: Bottom | F56: Maximum | G56: 0 | I56: Bottom | N56: Maximum | O56: 0 | Q56: Bottom | V56: Maximum | W56: 0
F57: Range | G57: 0 | N57: Range | O57: 0 | V57: Range | W57: 0
...

Sheet Env 02 Sep 26
A1: PV LAB EXPERIMENTAL DATA ENTRY TEMPLATE (DDM PARAMETER EXTRACTION)---2 September 2026
A4: 20260819-E02 – Temperature Grid (°C) | I4: 20260819-E02 – Irradiance Grid (W/m²) | Q4: 20260819-E02 – Temperature Grid After(°C)
A5: Position | B5: Left | C5: Centre | D5: Right | F5: Metric | I5: Position | J5: Left | K5: Centre | L5: Right | N5: Metric | Q5: Position | R5: Left | S5: Centre | T5: Right
A6: Top | B6: 21.3 | C6: 22.4 | D6: 21.1 | F6: Average | G6: =AVERAGE(B6:D8) -> 22.1 | I6: Top | J6: 252.5 | K6: 211.8 | L6: 205.5 | N6: Average | O6: =AVERAGE(J6:L8) -> 218.51111 | Q6: Top
A7: Middle | B7: 21.8 | C7: 25.3 | D7: 21.2 | F7: Minimum | G7: =MIN(B6:D8) -> 20.7 | I7: Middle | J7: 240.7 | K7: 215.5 | L7: 196.6 | N7: Minimum | O7: =MIN(J6:L80) -> 171.5 | Q7: Middle
A8: Bottom | B8: 20.7 | C8: 23.5 | D8: 21.6 | F8: Maximum | G8: =MAX(B6:D8) -> 25.3 | I8: Bottom | J8: 225 | K8: 227 | L8: 192 | N8: Maximum | O8: =MAX(J6:L8) -> 252.5 | Q8: Bottom
F9: Range | G9: 0 | N9: Range | O9: 0
A10: ENVIRONMENTAL & TEST CONDITIONS: | F10: Std | G10: #DIV/0! | N10: Uniform(%) | O10: #DIV/0!
A11: Lamp Distance (cm): | C11: Outside 15:45
A12: Fan Condition:
A13: Window Condition: | C13: Closed / unShielded
A14: Test Purpose / Notes:
A20: 20260819-E02 – Temperature Grid (°C) | I20: 20260819-E02 – Irradiance Grid (W/m²) | Q20: 20260819-E02 – Temperature Grid After(°C)
A21: Position | B21: Left | C21: Centre | D21: Right | F21: Metric | I21: Position | J21: Left | K21: Centre | L21: Right | N21: Metric | Q21: Position | R21: Left | S21: Centre | T21: Right
A22: Top | B22: 19.1 | C22: 19.5 | D22: 20.6 | F22: Average | G22: =AVERAGE(B22:D24) -> 19.577778 | I22: Top | J22: 171.5 | K22: 192.7 | L22: 177.8 | N22: Average | O22: =AVERAGE(J22:L24) -> 184.36667 | Q22: Top
A23: Middle | B23: 19 | C23: 20.2 | D23: 20.9 | F23: Minimum | G23: =MIN(B22:D24) -> 18 | I23: Middle | J23: 188.7 | K23: 201.5 | L23: 180.8 | N23: Minimum | O23: =MIN(J22:L96) -> 171.5 | Q23: Middle
A24: Bottom | B24: 18 | C24: 20.3 | D24: 18.6 | F24: Maximum | G24: =MAX(B22:D24) -> 20.9 | I24: Bottom | J24: 182.1 | K24: 192.3 | L24: 171.9 | N24: Maximum | O24: =MAX(J22:L24) -> 201.5 | Q24: Bottom
F25: Range | G25: 0 | N25: Range | O25: 0
A26: ENVIRONMENTAL & TEST CONDITIONS: | F26: Std | G26: #DIV/0! | N26: Uniform(%) | O26: #DIV/0!
A27: Lamp Distance (cm): | C27: Outside 16:00
A28: Fan Condition:
A29: Window Condition: | C29: Closed / unShielded
A30: Test Purpose / Notes:

Sheet Env 07 Sep 2026
A1: PV LAB EXPERIMENTAL DATA ENTRY TEMPLATE (DDM PARAMETER EXTRACTION)---7 September 2026
A4: 0.65625
A5: 20260819-E02 – Temperature Grid (°C) | I5: 20260819-E02 – Irradiance Grid (W/m²) | Q5: 20260819-E02 – Temperature Grid After(°C)
A6: Position | B6: Left | C6: Centre | D6: Right | F6: Metric | I6: Position | J6: Left | K6: Centre | L6: Right | N6: Metric | Q6: Position | R6: Left | S6: Centre | T6: Right | V6: Metric
A7: Top | B7: 51.7 | C7: 50.8 | D7: 53.5 | F7: Average | G7: =AVERAGE(B7:D9) -> 51.477778 | I7: Top | J7: 675 | K7: 607.2 | L7: 662.5 | N7: Average | O7: =AVERAGE(J7:L9) -> 651.12222 | Q7: Top | V7: Average | W7: =AVERAGE(R7:T9) -> #DIV/0!
A8: Middle | B8: 50.6 | C8: 51.8 | D8: 52.5 | F8: Minimum | G8: =MIN(B7:D9) -> 50.5 | I8: Middle | J8: 683.9 | K8: 685 | L8: 667.1 | N8: Minimum | O8: =MIN(J7:L9) -> 607.2 | Q8: Middle | V8: Minimum | W8: =MIN(R7:T9) -> 0
A9: Bottom | B9: 51 | C9: 50.5 | D9: 50.9 | F9: Maximum | G9: =MAX(B7:D9) -> 53.5 | I9: Bottom | J9: 615.8 | K9: 627.5 | L9: 636.1 | N9: Maximum | O9: =MAX(J7:L9) -> 685 | Q9: Bottom | V9: Maximum | W9: =MAX(R7:T9) -> 0
F10: Range | G10: =G9-G8 -> 3 | N10: Range | O10: =O9-O8 -> 77.8 | V10: Range | W10: =W9-W8 -> 0
A11: ENVIRONMENTAL & TEST CONDITIONS: | F11: Std | G11: =_xlfn.STDEV.S(B7:D9) -> 1.0022198 | N11: Uniform(%) | O11: =((MAX(J7:L9)-MIN(J7:L9))/(MAX(J7:L9)+MIN(J7:L9)))*100 -> 6.0207398 | V11: Std | W11: =_xlfn.STDEV.S(R7:T9) -> #DIV/0!
A12: Lamp Distance (cm): | C12: Outside
A13: Fan Condition:
A14: Window Condition: | C14: Closed / unShielded
A15: Test Purpose / Notes: | C15: Outside
A17: current
A18: voltage
A22: 0.66666667
A23: 20260819-E02 – Temperature Grid (°C) | I23: 20260819-E02 – Irradiance Grid (W/m²) | Q23: 20260819-E02 – Temperature Grid After(°C)
A24: Position | B24: Left | C24: Centre | D24: Right | F24: Metric | I24: Position | J24: Left | K24: Centre | L24: Right | N24: Metric | Q24: Position | R24: Left | S24: Centre | T24: Right
A25: Top | B25: 47.3 | C25: 47.8 | D25: 49.6 | F25: Average | G25: =AVERAGE(B25:D27) -> 48.833333 | I25: Top | J25: 613.8 | K25: 651.9 | L25: 632.8 | N25: Average | O25: =AVERAGE(J25:L27) -> 629.01111 | Q25: Top
A26: Middle | B26: 48 | C26: 51.4 | D26: 51.1 | F26: Minimum | G26: =MIN(B25:D27) -> 47.3 | I26: Middle | J26: 662.6 | K26: 626.8 | L26: 607.9 | N26: Minimum | O26: =MIN(J25:L27) -> 604.4 | Q26: Middle
A27: Bottom | B27: 47.8 | C27: 48.3 | D27: 48.2 | F27: Maximum | G27: =MAX(B25:D27) -> 51.4 | I27: Bottom | J27: 604.4 | K27: 630.8 | L27: 630.1 | N27: Maximum | O27: =MAX(J25:L27) -> 662.6 | Q27: Bottom
F28: Range | G28: =G27-G26 -> 4.1 | N28: Range | O28: =O27-O26 -> 58.2
A29: ENVIRONMENTAL & TEST CONDITIONS: | F29: Std | G29: =_xlfn.STDEV.S(B25:D27) -> 1.5074813 | N29: Uniform(%) | O29: =((MAX(J25:L27)-MIN(J25:L27))/(MAX(J25:L27)+MIN(J25:L27)))*100 -> 4.593528
A30: Lamp Distance (cm): | C30: Outside
A31: Fan Condition:
A32: Window Condition: | C32: Closed / unShielded
A33: Test Purpose / Notes: | C33: Outside
A38: 0.67708333
A39: 20260819-E02 – Temperature Grid (°C) | I39: 20260819-E02 – Irradiance Grid (W/m²)
A40: Position | B40: Left | C40: Centre | D40: Right | F40: Metric | I40: Position | J40: Left | K40: Centre | L40: Right | N40: Metric
A41: Top | B41: 45.4 | C41: 46.9 | D41: 47.5 | F41: Average | G41: =AVERAGE(B41:D43) -> 46.822222 | I41: Top | J41: 552.8 | K41: 619.1 | L41: 613.6 | N41: Average | O41: =AVERAGE(J41:L43) -> 592.91111
A42: Middle | B42: 45.3 | C42: 50 | D42: 49.1 | F42: Minimum | G42: =MIN(B41:D43) -> 44.2 | I42: Middle | J42: 604.6 | K42: 615.6 | L42: 585.9 | N42: Minimum | O42: =MIN(J41:L43) -> 552.8
A43: Bottom | B43: 44.2 | C43: 46.4 | D43: 46.6 | F43: Maximum | G43: =MAX(B41:D43) -> 50 | I43: Bottom | J43: 583.9 | K43: 559 | L43: 601.7 | N43: Maximum | O43: =MAX(J41:L43) -> 619.1
F44: Range | G44: =G43-G42 -> 5.8 | N44: Range | O44: =O43-O42 -> 66.3
A45: ENVIRONMENTAL & TEST CONDITIONS: | F45: Std | G45: =_xlfn.STDEV.S(B41:D43) -> 1.8437582 | N45: Uniform(%) | O45: =((MAX(J41:L43)-MIN(J41:L43))/(MAX(J41:L43)+MIN(J41:L43)))*100 -> 5.6574793
A46: Lamp Distance (cm): | C46: Outside
A47: Fan Condition:
A48: Window Condition: | C48: Closed / unShielded
A49: Test Purpose / Notes: | C49: Outside
A53: 0.6875
...

Sheet Env 17 Sep 2026
A2: CONSTANT irradiance VARYING temperature
J4: C=0.4170
A6: 20260819-E02 – Temperature Grid (°C) | I6: 20260819-E02 – Irradiance Grid (W/m²)
A7: Position | B7: Left | C7: Centre | D7: Right | F7: Metric | I7: Position | J7: Left | K7: Centre | L7: Right | N7: Metric
A8: Top | B8: 38 | C8: 39.5 | D8: 38.8 | F8: Average | G8: =AVERAGE(B8:D10) -> 38.644444 | I8: Top | J8: 334.1 | K8: 384.5 | L8: 337.4 | N8: Average | O8: =AVERAGE(J8:L10) -> 338.25556
A9: Middle | B9: 38.4 | C9: 39.6 | D9: 40 | F9: Minimum | G9: =MIN(B8:D10) -> 35.1 | I9: Middle | J9: 316.5 | K9: 371.3 | L9: 348.6 | N9: Minimum | O9: =MIN(J8:L10) -> 312.3
A10: Bottom | B10: 35.1 | C10: 39.5 | D10: 38.9 | F10: Maximum | G10: =MAX(B8:D10) -> 40 | I10: Bottom | J10: 312.3 | K10: 321.8 | L10: 317.8 | N10: Maximum | O10: =MAX(J8:L10) -> 384.5
F11: Range | G11: =G10-G9 -> 4.9 | N11: Range | O11: =O10-O9 -> 72.2
A12: ENVIRONMENTAL & TEST CONDITIONS: | F12: Std | G12: =_xlfn.STDEV.S(B8:D10) -> 1.4723375 | N12: Uniform(%) | O12: =((MAX(J8:L10)-MIN(J8:L10))/(MAX(J8:L10)+MIN(J8:L10)))*100 -> 10.361653
A13: Lamp Distance (cm): | C13: Inside variac voltage is 150V
A14: Fan Condition: | C14: off
A15: Window Condition: | C15: Closed / unShielded
A16: Test Purpose / Notes: | C16: constant irradiance, varying temperature
A19: 20260819-E02 – Temperature Grid (°C) | I19: 20260819-E02 – Irradiance Grid (W/m²)
A20: Position | B20: Left | C20: Centre | D20: Right | F20: Metric | I20: Position | J20: Left | K20: Centre | L20: Right | N20: Metric
A21: Top | B21: 28.5 | C21: 30.1 | D21: 30.6 | F21: Average | G21: =AVERAGE(B21:D23) -> 32.244444 | I21: Top | J21: 329.7 | K21: 380.3 | L21: 304.6 | N21: Average | O21: =AVERAGE(J21:L23) -> 340.23333
A22: Middle | B22: 31 | C22: 32 | D22: 32.8 | F22: Minimum | G22: =MIN(B21:D23) -> 28.5 | I22: Middle | J22: 307 | K22: 385 | L22: 340.7 | N22: Minimum | O22: =MIN(J21:L23) -> 304.6
A23: Bottom | B23: 34.3 | C23: 35.1 | D23: 35.8 | F23: Maximum | G23: =MAX(B21:D23) -> 35.8 | I23: Bottom | J23: 306.3 | K23: 368.5 | L23: 340 | N23: Maximum | O23: =MAX(J21:L23) -> 385
F24: Range | G24: =G23-G22 -> 7.3 | N24: Range | O24: =O23-O22 -> 80.4
A25: ENVIRONMENTAL & TEST CONDITIONS: | F25: Std | G25: =_xlfn.STDEV.S(B21:D23) -> 2.4561714 | N25: Uniform(%) | O25: =((MAX(J21:L23)-MIN(J21:L23))/(MAX(J21:L23)+MIN(J21:L23)))*100 -> 11.658933
A26: Lamp Distance (cm): | C26: Inside variac voltage = 150 V
A27: Fan Condition: | C27: On
A28: Window Condition: | C28: Closed / unShielded
A29: Test Purpose / Notes: | C29: constant irradiance, varying temperature
A33: 20260819-E02 – Temperature Grid (°C) | I33: 20260819-E02 – Irradiance Grid (W/m²)
A34: Position | B34: Left | C34: Centre | D34: Right | F34: Metric | I34: Position | J34: Left | K34: Centre | L34: Right | N34: Metric
A35: Top | B35: 42.2 | C35: 46 | D35: 46.1 | F35: Average | G35: =AVERAGE(B35:D37) -> 45.7 | I35: Top | J35: 335.4 | K35: 412.7 | L35: 341.1 | N35: Average | O35: =AVERAGE(J35:L37) -> 370.5625
A36: Middle | B36: 45.5 | C36: 47.2 | D36: 46.8 | F36: Minimum | G36: =MIN(B35:D37) -> 42.2 | I36: Middle | J36: 346 | K36: 425.9 | L36: 402.2 | N36: Minimum | O36: =MIN(J35:L37) -> 331.4
A37: Bottom | B37: 43 | C37: 48 | D37: 46.5 | F37: Maximum | G37: =MAX(B35:D37) -> 48 | I37: Bottom | J37: 331.4 | K37: 409..4 | L37: 369.8 | N37: Maximum | O37: =MAX(J35:L37) -> 425.9
F38: Range | G38: =G37-G36 -> 5.8 | N38: Range | O38: =O37-O36 -> 94.5
A39: ENVIRONMENTAL & TEST CONDITIONS: | F39: Std | G39: =_xlfn.STDEV.S(B35:D37) -> 1.9111515 | N39: Uniform(%) | O39: =((MAX(J35:L37)-MIN(J35:L37))/(MAX(J35:L37)+MIN(J35:L37)))*100 -> 12.478542
A40: Lamp Distance (cm): | C40: Inside varic voltage = 150V
A41: Fan Condition: | C41: On
A42: Window Condition: | C42: Closed / unShielded
A43: Test Purpose / Notes: | C43: constant irradiance, varying temperature
A47: 20260819-E02 – Temperature Grid (°C) | I47: 20260819-E02 – Irradiance Grid (W/m²)
A48: Position | B48: Left | C48: Centre | D48: Right | F48: Metric | I48: Position | J48: Left | K48: Centre | L48: Right | N48: Metric
A49: Top | B49: 47.3 | C49: 47.8 | D49: 49.6 | F49: Average | G49: =AVERAGE(B49:D51) -> 48.833333 | I49: Top | J49: 613.8 | K49: 651.9 | L49: 632.8 | N49: Average | O49: =AVERAGE(J49:L51) -> 629.01111
A50: Middle | B50: 48 | C50: 51.4 | D50: 51.1 | F50: Minimum | G50: =MIN(B49:D51) -> 47.3 | I50: Middle | J50: 662.6 | K50: 626.8 | L50: 607.9 | N50: Minimum | O50: =MIN(J49:L51) -> 604.4
A51: Bottom | B51: 47.8 | C51: 48.3 | D51: 48.2 | F51: Maximum | G51: =MAX(B49:D51) -> 51.4 | I51: Bottom | J51: 604.4 | K51: 630.8 | L51: 630.1 | N51: Maximum | O51: =MAX(J49:L51) -> 662.6
...

Sheet Env 18 Sep 2026
J1: c=0.4170
A2: CONSTANT irradiance VARYING temperature
A6: 20260918-E02 – Temperature Grid (°C) | I6: 20260918-E02 – Irradiance Grid (W/m²)
A7: Position | B7: Left | C7: Centre | D7: Right | F7: Metric | I7: Position | J7: Left | K7: Centre | L7: Right | N7: Metric
A8: Top | B8: 27.9 | C8: 30.8 | D8: 31.2 | F8: Average | G8: =AVERAGE(B8:D10) -> 30.677778 | I8: Top | J8: 312.5 | K8: 355.5 | L8: 301.2 | N8: Average | O8: =AVERAGE(J8:L10) -> 333.98889
A9: Middle | B9: 29.7 | C9: 31.9 | D9: 32.1 | F9: Minimum | G9: =MIN(B8:D10) -> 27.9 | I9: Middle | J9: 315.8 | K9: 371.3 | L9: 350 | N9: Minimum | O9: =MIN(J8:L10) -> 301.2
A10: Bottom | B10: 29 | C10: 32.2 | D10: 31.3 | F10: Maximum | G10: =MAX(B8:D10) -> 32.2 | I10: Bottom | J10: 309 | K10: 359.2 | L10: 331.4 | N10: Maximum | O10: =MAX(J8:L10) -> 371.3
F11: Range | G11: =G10-G9 -> 4.3 | N11: Range | O11: =O10-O9 -> 70.1
A12: ENVIRONMENTAL & TEST CONDITIONS: | F12: Std | G12: =_xlfn.STDEV.S(B8:D10) -> 1.4998148 | N12: Uniform(%) | O12: =((MAX(J8:L10)-MIN(J8:L10))/(MAX(J8:L10)+MIN(J8:L10)))*100 -> 10.423792
A13: Lamp Distance (cm): | C13: Inside variac voltage is 150V
A14: Fan Condition: | C14: off
A15: Window Condition: | C15: Closed / unShielded
A16: Test Purpose / Notes: | C16: constant irradiance, varying temperature
A20: 20260819-E02 – Temperature Grid (°C) | I20: 20260819-E02 – Irradiance Grid (W/m²)
A21: Position | B21: Left | C21: Centre | D21: Right | F21: Metric | I21: Position | J21: Left | K21: Centre | L21: Right | N21: Metric
A22: Top | B22: 40.4 | C22: 43.6 | D22: 43.5 | F22: Average | G22: =AVERAGE(B22:D24) -> 42.877778 | I22: Top | J22: 305.2 | K22: 354.8 | L22: 300.4 | N22: Average | O22: =AVERAGE(J22:L24) -> 334.22222
A23: Middle | B23: 43.1 | C23: 44 | D23: 43.3 | F23: Minimum | G23: =MIN(B22:D24) -> 40.4 | I23: Middle | J23: 312.9 | K23: 384.3 | L23: 358.5 | N23: Minimum | O23: =MIN(J22:L24) -> 300.4
A24: Bottom | B24: 40.5 | C24: 44.2 | D24: 43.3 | F24: Maximum | G24: =MAX(B22:D24) -> 44.2 | I24: Bottom | J24: 308.5 | K24: 362.5 | L24: 320.9 | N24: Maximum | O24: =MAX(J22:L24) -> 384.3
F25: Range | G25: =G24-G23 -> 3.8 | N25: Range | O25: =O24-O23 -> 83.9
A26: ENVIRONMENTAL & TEST CONDITIONS: | F26: Std | G26: =_xlfn.STDEV.S(B22:D24) -> 1.4193113 | N26: Uniform(%) | O26: =((MAX(J22:L24)-MIN(J22:L24))/(MAX(J22:L24)+MIN(J22:L24)))*100 -> 12.253542
A27: Lamp Distance (cm): | C27: Inside variac voltage is 150V
A28: Fan Condition: | C28: off
A29: Window Condition: | C29: Closed / unShielded
A30: Test Purpose / Notes: | C30: constant irradiance, varying temperature

Sheet Env 22 Sep 2026 
A1: IV CURVES ACROSS DIFFERENT IRRADIANCE AND TEMPERATURE RANGES THAT WILL BE USED TO VALIDATE THE SDM
A5: 20260819-E02 – Temperature Grid (°C) | I5: 20260819-E02 – Irradiance Grid (W/m²)
A6: Position | B6: Left | C6: Centre | D6: Right | F6: Metric | I6: Position | J6: Left | K6: Centre | L6: Right | N6: Metric
A7: Top | B7: 34.2 | C7: 36 | D7: 36.4 | F7: Average | G7: =AVERAGE(B7:D9) -> 36.222222 | I7: Top | J7: 181 | K7: 203.9 | L7: 202.2 | N7: Average | O7: =AVERAGE(J7:L9) -> 208.24444
A8: Middle | B8: 35.9 | C8: 36.7 | D8: 37 | F8: Minimum | G8: =MIN(B7:D9) -> 34.2 | I8: Middle | J8: 204.6 | K8: 229.7 | L8: 229.2 | N8: Minimum | O8: =MIN(J7:L9) -> 181
A9: Bottom | B9: 36.2 | C9: 37 | D9: 36.6 | F9: Maximum | G9: =MAX(B7:D9) -> 37 | I9: Bottom | J9: 198 | K9: 215.1 | L9: 210.5 | N9: Maximum | O9: =MAX(J7:L9) -> 229.7
F10: Range | G10: =G9-G8 -> 2.8 | N10: Range | O10: =O9-O8 -> 48.7
A11: ENVIRONMENTAL & TEST CONDITIONS: | F11: Std | G11: =_xlfn.STDEV.S(B7:D9) -> 0.85553752 | N11: Uniform(%) | O11: =((MAX(J7:L9)-MIN(J7:L9))/(MAX(J7:L9)+MIN(J7:L9)))*100 -> 11.857804
A12: Lamp Distance (cm): | C12: Inside variac voltage is 150V
A13: Fan Condition: | C13: Off, distance is 90 cm
A14: Window Condition: | C14: Closed / unShielded
A15: Test Purpose / Notes: | C15: Validation data-
A19: 20260819-E02 – Temperature Grid (°C) | I19: 20260819-E02 – Irradiance Grid (W/m²)
A20: Position | B20: Left | C20: Centre | D20: Right | F20: Metric | I20: Position | J20: Left | K20: Centre | L20: Right | N20: Metric
A21: Top | B21: 38.6 | C21: 40.7 | D21: 41.4 | F21: Average | G21: =AVERAGE(B21:D23) -> 41.111111 | I21: Top | J21: 281.9 | K21: 321.1 | L21: 315.6 | N21: Average | O21: =AVERAGE(J21:L23) -> 322.07778
A22: Middle | B22: 42.8 | C22: 42 | D22: 42.1 | F22: Minimum | G22: =MIN(B21:D23) -> 38.6 | I22: Middle | J22: 321.8 | K22: 353.3 | L22: 351.5 | N22: Minimum | O22: =MIN(J21:L23) -> 281.9
A23: Bottom | B23: 39.6 | C23: 41.5 | D23: 41.3 | F23: Maximum | G23: =MAX(B21:D23) -> 42.8 | I23: Bottom | J23: 303.7 | K23: 326.2 | L23: 323.6 | N23: Maximum | O23: =MAX(J21:L23) -> 353.3
F24: Range | G24: =G23-G22 -> 4.2 | N24: Range | O24: =O23-O22 -> 71.4
A25: ENVIRONMENTAL & TEST CONDITIONS: | F25: Std | G25: =_xlfn.STDEV.S(B21:D23) -> 1.3061819 | N25: Uniform(%) | O25: =((MAX(J21:L23)-MIN(J21:L23))/(MAX(J21:L23)+MIN(J21:L23)))*100 -> 11.240554
A26: Lamp Distance (cm): | C26: Inside variac voltage is 180V
A27: Fan Condition: | C27: off, distance is 90cm
A28: Window Condition: | C28: Closed / unShielded
A29: Test Purpose / Notes: | C29: Validation data-
A34: 20260819-E02 – Temperature Grid (°C) | I34: 20260819-E02 – Irradiance Grid (W/m²)
A35: Position | B35: Left | C35: Centre | D35: Right | F35: Metric | I35: Position | J35: Left | K35: Centre | L35: Right | N35: Metric
A36: Top | B36: 41.2 | C36: 43.3 | D36: 45.2 | F36: Average | G36: =AVERAGE(B36:D38) -> 45.033333 | I36: Top | J36: 335.4 | K36: 401.5 | L36: 380.3 | N36: Average | O36: =AVERAGE(J36:L38) -> 398.53333
A37: Middle | B37: 44 | C37: 46.3 | D37: 46.6 | F37: Minimum | G37: =MIN(B36:D38) -> 41.2 | I37: Middle | J37: 402.2 | K37: 443.1 | L37: 439.4 | N37: Minimum | O37: =MIN(J36:L38) -> 335.4
A38: Bottom | B38: 46 | C38: 46.5 | D38: 46.2 | F38: Maximum | G38: =MAX(B36:D38) -> 46.6 | I38: Bottom | J38: 379 | K38: 402.2 | L38: 403.7 | N38: Maximum | O38: =MAX(J36:L38) -> 443.1
F39: Range | G39: =G38-G37 -> 5.4 | N39: Range | O39: =O38-O37 -> 107.7
A40: ENVIRONMENTAL & TEST CONDITIONS: | F40: Std | G40: =_xlfn.STDEV.S(B36:D38) -> 1.8472953 | N40: Uniform(%) | O40: =((MAX(J36:L38)-MIN(J36:L38))/(MAX(J36:L38)+MIN(J36:L38)))*100 -> 13.834297
A41: Lamp Distance (cm): | C41: Inside variac voltage is 200V
A42: Fan Condition: | C42: On
A43: Window Condition: | C43: Closed / unShielded
A44: Test Purpose / Notes: | C44: Validation data-
A48: 20260819-E02 – Temperature Grid (°C) | I48: 20260819-E02 – Irradiance Grid (W/m²)
A49: Position | B49: Left | C49: Centre | D49: Right | F49: Metric | I49: Position | J49: Left | K49: Centre | L49: Right | N49: Metric
A50: Top | B50: 44.6 | C50: 47.2 | D50: 47 | F50: Average | G50: =AVERAGE(B50:D52) -> 48.944444 | I50: Top | J50: 440.5 | K50: 514 | L50: 510.1 | N50: Average | O50: =AVERAGE(J50:L52) -> 522.63333
A51: Middle | B51: 50.9 | C51: 51.1 | D51: 50.8 | F51: Minimum | G51: =MIN(B50:D52) -> 44.6 | I51: Middle | J51: 533 | K51: 580.6 | L51: 564 | N51: Minimum | O51: =MIN(J50:L52) -> 440.5
A52: Bottom | B52: 47.5 | C52: 50 | D52: 51.4 | F52: Maximum | G52: =MAX(B50:D52) -> 51.4 | I52: Bottom | J52: 503.9 | K52: 531.2 | L52: 526.4 | N52: Maximum | O52: =MAX(J50:L52) -> 580.6
F53: Range | G53: =G52-G51 -> 6.8 | N53: Range | O53: =O52-O51 -> 140.1
...

Sheet Env 23 Sep 2026 
A1: IV CURVES ACROSS DIFFERENT IRRADIANCE AND TEMPERATURE RANGES THAT WILL BE USED TO VALIDATE THE SDM
A5: 20260819-E02 – Temperature Grid (°C) | I5: 20260819-E02 – Irradiance Grid (W/m²)
A6: Position | B6: Left | C6: Centre | D6: Right | F6: Metric | I6: Position | J6: Left | K6: Centre | L6: Right | N6: Metric
A7: Top | B7: 30.2 | C7: 31.7 | D7: 31.5 | F7: Average | G7: =AVERAGE(B7:D9) -> 32.577778 | I7: Top | J7: 350 | K7: 403.5 | L7: 377.9 | N7: Average | O7: =AVERAGE(J7:L9) -> 394.71111
A8: Middle | B8: 32.5 | C8: 33.5 | D8: 33.4 | F8: Minimum | G8: =MIN(B7:D9) -> 30.2 | I8: Middle | J8: 402.8 | K8: 444 | L8: 411.6 | N8: Minimum | O8: =MIN(J7:L9) -> 350
A9: Bottom | B9: 32.3 | C9: 34.4 | D9: 33.7 | F9: Maximum | G9: =MAX(B7:D9) -> 34.4 | I9: Bottom | J9: 378.6 | K9: 403 | L9: 381 | N9: Maximum | O9: =MAX(J7:L9) -> 444
F10: Range | G10: =G9-G8 -> 4.2 | N10: Range | O10: =O9-O8 -> 94
A11: ENVIRONMENTAL & TEST CONDITIONS: | F11: Std | G11: =_xlfn.STDEV.S(B7:D9) -> 1.3122288 | N11: Uniform(%) | O11: =((MAX(J7:L9)-MIN(J7:L9))/(MAX(J7:L9)+MIN(J7:L9)))*100 -> 11.838791
A12: Lamp Distance (cm): | C12: Inside variac voltage is 200V
A13: Fan Condition: | C13: ON, distance is 90 cm
A14: Window Condition: | C14: Closed / unShielded
A15: Test Purpose / Notes: | C15: Validation data-constant irradiance varying temperature
A19: 20260819-E02 – Temperature Grid (°C) | I19: 20260819-E02 – Irradiance Grid (W/m²)
A20: Position | B20: Left | C20: Centre | D20: Right | F20: Metric | I20: Position | J20: Left | K20: Centre | L20: Right | N20: Metric
A21: Top | B21: 40.4 | C21: 42.2 | D21: 43.5 | F21: Average | G21: =AVERAGE(B21:D23) -> 43.177778 | I21: Top | J21: 357.9 | K21: 416.2 | L21: 385 | N21: Average | O21: =AVERAGE(J21:L23) -> 402.31111
A22: Middle | B22: 44 | C22: 44.5 | D22: 44.3 | F22: Minimum | G22: =MIN(B21:D23) -> 40.4 | I22: Middle | J22: 405.5 | K22: 450.4 | L22: 418.7 | N22: Minimum | O22: =MIN(J21:L23) -> 357.9
A23: Bottom | B23: 42.4 | C23: 43.5 | D23: 43.8 | F23: Maximum | G23: =MAX(B21:D23) -> 44.5 | I23: Bottom | J23: 385 | K23: 418.2 | L23: 383.9 | N23: Maximum | O23: =MAX(J21:L23) -> 450.4
F24: Range | G24: =G23-G22 -> 4.1 | N24: Range | O24: =O23-O22 -> 92.5
A25: ENVIRONMENTAL & TEST CONDITIONS: | F25: Std | G25: =_xlfn.STDEV.S(B21:D23) -> 1.3017083 | N25: Uniform(%) | O25: =((MAX(J21:L23)-MIN(J21:L23))/(MAX(J21:L23)+MIN(J21:L23)))*100 -> 11.443771
A26: Lamp Distance (cm): | C26: Inside variac voltage is 200V
A27: Fan Condition: | C27: Off, distance is 90 cm
A28: Window Condition: | C28: Closed / unShielded
A29: Test Purpose / Notes: | C29: Validation data-constant irradiance varying temperature
A32: 20260819-E02 – Temperature Grid (°C) | I32: 20260819-E02 – Irradiance Grid (W/m²)
A33: Position | B33: Left | C33: Centre | D33: Right | F33: Metric | I33: Position | J33: Left | K33: Centre | L33: Right | N33: Metric
A34: Top | B34: 40.3 | C34: 43 | D34: 43.8 | F34: Average | G34: =AVERAGE(B34:D36) -> 43.288889 | I34: Top | J34: 350.2 | K34: 406.1 | L34: 377.9 | N34: Average | O34: =AVERAGE(J34:L36) -> 395.27778
A35: Middle | B35: 44.8 | C35: 44.5 | D35: 44.5 | F35: Minimum | G35: =MIN(B34:D36) -> 40.3 | I35: Middle | J35: 402.2 | K35: 455.2 | L35: 417.4 | N35: Minimum | O35: =MIN(J34:L36) -> 350.2
A36: Bottom | B36: 41.5 | C36: 43.6 | D36: 43.6 | F36: Maximum | G36: =MAX(B34:D36) -> 44.8 | I36: Bottom | J36: 377 | K36: 393.6 | L36: 377.9 | N36: Maximum | O36: =MAX(J34:L36) -> 455.2
F37: Range | G37: =G36-G35 -> 4.5 | N37: Range | O37: =O36-O35 -> 105
A38: ENVIRONMENTAL & TEST CONDITIONS: | F38: Std | G38: =_xlfn.STDEV.S(B34:D36) -> 1.4953632 | N38: Uniform(%) | O38: =((MAX(J34:L36)-MIN(J34:L36))/(MAX(J34:L36)+MIN(J34:L36)))*100 -> 13.037
A39: Lamp Distance (cm): | C39: Inside variac voltage is 200V
A40: Fan Condition: | C40: Off, distance is 90 cm
A41: Window Condition: | C41: Closed / unShielded
A42: Test Purpose / Notes: | C42: Validation data-constant irradiance varying temperature
A44: 20260819-E02 – Temperature Grid (°C) | I44: 20260819-E02 – Irradiance Grid (W/m²)
A45: Position | B45: Left | C45: Centre | D45: Right | F45: Metric | I45: Position | J45: Left | K45: Centre | L45: Right | N45: Metric
A46: Top | B46: 34.7 | C46: 35 | D46: 35.6 | F46: Average | G46: =AVERAGE(B46:D48) -> 37.544444 | I46: Top | J46: 348.6 | K46: 406 | L46: 379 | N46: Average | O46: =AVERAGE(J46:L48) -> 393.16667
A47: Middle | B47: 38.5 | C47: 39.5 | D47: 38.1 | F47: Minimum | G47: =MIN(B46:D48) -> 34.7 | I47: Middle | J47: 396.9 | K47: 437.8 | L47: 414.7 | N47: Minimum | O47: =MIN(J46:L48) -> 348.6
A48: Bottom | B48: 38 | C48: 39.5 | D48: 39 | F48: Maximum | G48: =MAX(B46:D48) -> 39.5 | I48: Bottom | J48: 377 | K48: 402.8 | L48: 375.7 | N48: Maximum | O48: =MAX(J46:L48) -> 437.8
F49: Range | G49: =G48-G47 -> 4.8 | N49: Range | O49: =O48-O47 -> 89.2
...

Sheet Env 25Sep 2026
A1: IV CURVES ACROSS DIFFERENT IRRADIANCE AND TEMPERATURE RANGES THAT WILL BE USED TO VALIDATE THE SDM
A5: 20260819-E02 – Temperature Grid (°C) | I5: 20260819-E02 – Irradiance Grid (W/m²)
A6: Position | B6: Left | C6: Centre | D6: Right | F6: Metric | I6: Position | J6: Left | K6: Centre | L6: Right | N6: Metric
A7: Top | B7: 27.4 | C7: 28 | D7: 28 | F7: Average | G7: =AVERAGE(B7:D9) -> 29 | I7: Top | J7: 193.6 | K7: 206.1 | L7: 197.5 | N7: Average | O7: =AVERAGE(J7:L9) -> 206.54444
A8: Middle | B8: 31.4 | C8: 29.5 | D8: 29 | F8: Minimum | G8: =MIN(B7:D9) -> 27.4 | I8: Middle | J8: 213.8 | K8: 229.7 | L8: 213.2 | N8: Minimum | O8: =MIN(J7:L9) -> 193.6
A9: Bottom | B9: 29 | C9: 29.4 | D9: 29.3 | F9: Maximum | G9: =MAX(B7:D9) -> 31.4 | I9: Bottom | J9: 197.3 | K9: 207.2 | L9: 200.5 | N9: Maximum | O9: =MAX(J7:L9) -> 229.7
F10: Range | G10: =G9-G8 -> 4 | N10: Range | O10: =O9-O8 -> 36.1
A11: ENVIRONMENTAL & TEST CONDITIONS: | F11: Std | G11: =_xlfn.STDEV.S(B7:D9) -> 1.1629703 | N11: Uniform(%) | O11: =((MAX(J7:L9)-MIN(J7:L9))/(MAX(J7:L9)+MIN(J7:L9)))*100 -> 8.5282306
A12: Lamp Distance (cm): | C12: Inside variac voltage is 150V
A13: Fan Condition: | C13: ON, distance is 90 cm
A14: Window Condition: | C14: Closed / unShielded
A15: Test Purpose / Notes: | C15: Validation data-constant temperature varying irradiance
A20: 20260819-E02 – Temperature Grid (°C) | I20: 20260819-E02 – Irradiance Grid (W/m²)
A21: Position | B21: Left | C21: Centre | D21: Right | F21: Metric | I21: Position | J21: Left | K21: Centre | L21: Right | N21: Metric
A22: Top | B22: 29.5 | C22: 30.1 | D22: 30.4 | F22: Average | G22: =AVERAGE(B22:D24) -> 31.077778 | I22: Top | J22: 281.9 | K22: 312.9 | L22: 307 | N22: Average | O22: =AVERAGE(J22:L24) -> 318.15556
A23: Middle | B23: 31.6 | C23: 32 | D23: 31.4 | F23: Minimum | G23: =MIN(B22:D24) -> 29.5 | I23: Middle | J23: 321.8 | K23: 351.9 | L23: 324.2 | N23: Minimum | O23: =MIN(J22:L24) -> 281.9
A24: Bottom | B24: 31.3 | C24: 31.9 | D24: 31.5 | F24: Maximum | G24: =MAX(B22:D24) -> 32 | I24: Bottom | J24: 304.6 | K24: 352.1 | L24: 307 | N24: Maximum | O24: =MAX(J22:L24) -> 352.1
F25: Range | G25: =G24-G23 -> 2.5 | N25: Range | O25: =O24-O23 -> 70.2
A26: ENVIRONMENTAL & TEST CONDITIONS: | F26: Std | G26: =_xlfn.STDEV.S(B22:D24) -> 0.86858761 | N26: Uniform(%) | O26: =((MAX(J22:L24)-MIN(J22:L24))/(MAX(J22:L24)+MIN(J22:L24)))*100 -> 11.072555
A27: Lamp Distance (cm): | C27: Inside variac voltage is 180V
A28: Fan Condition: | C28: ON, distance is 90 cm
A29: Window Condition: | C29: Closed / unShielded
A30: Test Purpose / Notes: | C30: Validation data-constant temperature varying irradiance
A33: 20260819-E02 – Temperature Grid (°C) | I33: 20260819-E02 – Irradiance Grid (W/m²)
A34: Position | B34: Left | C34: Centre | D34: Right | F34: Metric | I34: Position | J34: Left | K34: Centre | L34: Right | N34: Metric
A35: Top | B35: 29.5 | C35: 30.4 | D35: 31 | F35: Average | G35: =AVERAGE(B35:D37) -> 31.633333 | I35: Top | J35: 342.2 | K35: 406.1 | L35: 366.5 | N35: Average | O35: =AVERAGE(J35:L37) -> 394.67778
A36: Middle | B36: 31.5 | C36: 32.6 | D36: 32.5 | F36: Minimum | G36: =MIN(B35:D37) -> 29.5 | I36: Middle | J36: 405.7 | K36: 447.7 | L36: 405 | N36: Minimum | O36: =MIN(J35:L37) -> 342.2
A37: Bottom | B37: 32 | C37: 32.4 | D37: 32.8 | F37: Maximum | G37: =MAX(B35:D37) -> 32.8 | I37: Bottom | J37: 386.3 | K37: 414 | L37: 378.6 | N37: Maximum | O37: =MAX(J35:L37) -> 447.7
F38: Range | G38: =G37-G36 -> 3.3 | N38: Range | O38: =O37-O36 -> 105.5
A39: ENVIRONMENTAL & TEST CONDITIONS: | F39: Std | G39: =_xlfn.STDEV.S(B35:D37) -> 1.1324752 | N39: Uniform(%) | O39: =((MAX(J35:L37)-MIN(J35:L37))/(MAX(J35:L37)+MIN(J35:L37)))*100 -> 13.356121
A40: Lamp Distance (cm): | C40: Inside variac voltage is 200V
A41: Fan Condition: | C41: ON, distance is 90 cm
A42: Window Condition: | C42: Closed / unShielded
A43: Test Purpose / Notes: | C43: Validation data-constant temperature varying irradiance
A46: 20260819-E02 – Temperature Grid (°C) | I46: 20260819-E02 – Irradiance Grid (W/m²)
A47: Position | B47: Left | C47: Centre | D47: Right | F47: Metric | I47: Position | J47: Left | K47: Centre | L47: Right | N47: Metric
A48: Top | B48: 30.7 | C48: 32.4 | D48: 33 | F48: Average | G48: =AVERAGE(B48:D50) -> 33.744444 | I48: Top | J48: 455.2 | K48: 506.1 | L48: 462.5 | N48: Average | O48: =AVERAGE(J48:L50) -> 501.21111
A49: Middle | B49: 33.7 | C49: 35 | D49: 35 | F49: Minimum | G49: =MIN(B48:D50) -> 30.7 | I49: Middle | J49: 513.8 | K49: 562.1 | L49: 520.4 | N49: Minimum | O49: =MIN(J48:L50) -> 455.2
A50: Bottom | B50: 33.4 | C50: 35.5 | D50: 35 | F50: Maximum | G50: =MAX(B48:D50) -> 35.5 | I50: Bottom | J50: 483.4 | K50: 521.1 | L50: 486.3 | N50: Maximum | O50: =MAX(J48:L50) -> 562.1
F51: Range | G51: =G50-G49 -> 4.8 | N51: Range | O51: =O50-O49 -> 106.9
...

Sheet Env 28 Sep 2026
A1: ENV FOR PARTIAL SHADING CONDITIONS
A3: 20260819-E02 – Temperature Grid (°C) | I3: 20260819-E02 – Irradiance Grid (W/m²)
A4: Position | B4: Left | C4: Centre | D4: Right | F4: Metric | I4: Position | J4: Left | K4: Centre | L4: Right | N4: Metric
A5: Top | B5: 39.6 | C5: 43.5 | D5: 45.2 | F5: Average | G5: =AVERAGE(B5:D7) -> 44.488889 | I5: Top | J5: 651.5 | K5: 761 | L5: 716.7 | N5: Average | O5: =AVERAGE(J5:L7) -> 742.66667
A6: Middle | B6: 43.5 | C6: 46.5 | D6: 46.8 | F6: Minimum | G6: =MIN(B5:D7) -> 39.6 | I6: Middle | J6: 701.5 | K6: 819.8 | L6: 811.4 | N6: Minimum | O6: =MIN(J5:L7) -> 651.5
A7: Bottom | B7: 42 | C7: 46.4 | D7: 46.9 | F7: Maximum | G7: =MAX(B5:D7) -> 46.9 | I7: Bottom | J7: 677 | K7: 796 | L7: 749.1 | N7: Maximum | O7: =MAX(J5:L7) -> 819.8
F8: Range | G8: =G7-G6 -> 7.3 | N8: Range | O8: =O7-O6 -> 168.3
A9: ENVIRONMENTAL & TEST CONDITIONS: | F9: Std | G9: =_xlfn.STDEV.S(B5:D7) -> 2.5349775 | N9: Uniform(%) | O9: =((MAX(J5:L7)-MIN(J5:L7))/(MAX(J5:L7)+MIN(J5:L7)))*100 -> 11.438864
A10: Lamp Distance (cm): | C10: Inside variac voltage is 220V
A11: Fan Condition: | C11: Off, distance is 60 cm
A12: Window Condition: | C12: Closed / unShielded
A13: Test Purpose / Notes: | C13: Partial shading cell:Column 1 Row 1
A15: 20260819-E02 – Temperature Grid (°C) | I15: 20260819-E02 – Irradiance Grid (W/m²)
A16: Position | B16: Left | C16: Centre | D16: Right | F16: Metric | I16: Position | J16: Left | K16: Centre | L16: Right | N16: Metric
A17: Top | B17: 43.6 | C17: 50.7 | D17: 51.5 | F17: Average | G17: =AVERAGE(B17:D19) -> 50.622222 | I17: Top | J17: 632.1 | K17: 764.8 | L17: 740.2 | N17: Average | O17: =AVERAGE(J17:L19) -> 749.4
A18: Middle | B18: 48.4 | C18: 54.8 | D18: 53.5 | F18: Minimum | G18: =MIN(B17:D19) -> 43.6 | I18: Middle | J18: 678.4 | K18: 821.8 | L18: 850.2 | N18: Minimum | O18: =MIN(J17:L19) -> 632.1
A19: Bottom | B19: 47.5 | C19: 52.8 | D19: 52.8 | F19: Maximum | G19: =MAX(B17:D19) -> 54.8 | I19: Bottom | J19: 658.5 | K19: 800 | L19: 798.6 | N19: Maximum | O19: =MAX(J17:L19) -> 850.2
F20: Range | G20: =G19-G18 -> 11.2 | N20: Range | O20: =O19-O18 -> 218.1
A21: ENVIRONMENTAL & TEST CONDITIONS: | F21: Std | G21: =_xlfn.STDEV.S(B17:D19) -> 3.5354553 | N21: Uniform(%) | O21: =((MAX(J17:L19)-MIN(J17:L19))/(MAX(J17:L19)+MIN(J17:L19)))*100 -> 14.713621
A22: Lamp Distance (cm): | C22: Inside variac voltage is 220V
A23: Fan Condition: | C23: Off, distance is 60 cm
A24: Window Condition: | C24: Closed / unShielded
A25: Test Purpose / Notes: | C25: Partial shading cell:Column 1 Row 11
A27: 20260819-E02 – Temperature Grid (°C) | I27: 20260819-E02 – Irradiance Grid (W/m²)
A28: Position | B28: Left | C28: Centre | D28: Right | F28: Metric | I28: Position | J28: Left | K28: Centre | L28: Right | N28: Metric
A29: Top | B29: 49 | C29: 50.4 | D29: 51.3 | F29: Average | G29: =AVERAGE(B29:D31) -> 50.711111 | I29: Top | J29: 646.5 | K29: 757 | L29: 739.4 | N29: Average | O29: =AVERAGE(J29:L31) -> 749.51111
A30: Middle | B30: 48.5 | C30: 51.7 | D30: 52.7 | F30: Minimum | G30: =MIN(B29:D31) -> 47.5 | I30: Middle | J30: 674.4 | K30: 839.2 | L30: 830.3 | N30: Minimum | O30: =MIN(J29:L31) -> 646.5
A31: Bottom | B31: 47.5 | C31: 52.5 | D31: 52.8 | F31: Maximum | G31: =MAX(B29:D31) -> 52.8 | I31: Bottom | J31: 662.7 | K31: 799.5 | L31: 796.6 | N31: Maximum | O31: =MAX(J29:L31) -> 839.2
F32: Range | G32: =G31-G30 -> 5.3 | N32: Range | O32: =O31-O30 -> 192.7
A33: ENVIRONMENTAL & TEST CONDITIONS: | F33: Std | G33: =_xlfn.STDEV.S(B29:D31) -> 1.970688 | N33: Uniform(%) | O33: =((MAX(J29:L31)-MIN(J29:L31))/(MAX(J29:L31)+MIN(J29:L31)))*100 -> 12.970317
A34: Lamp Distance (cm): | C34: Inside variac voltage is 220V | H34: TEMP OF THE COVERED CELL = 45.7
A35: Fan Condition: | C35: Off, distance is 60 cm
A36: Window Condition: | C36: Closed / unShielded
A37: Test Purpose / Notes: | C37: Partial shading cell:Column 3 Row 1
A39: 20260819-E02 – Temperature Grid (°C) | I39: 20260819-E02 – Irradiance Grid (W/m²)
A40: Position | B40: Left | C40: Centre | D40: Right | F40: Metric | I40: Position | J40: Left | K40: Centre | L40: Right | N40: Metric
A41: Top | B41: 48 | C41: 50 | D41: 50.2 | F41: Average | G41: =AVERAGE(B41:D43) -> 50.366667 | I41: Top | J41: 624.2 | K41: 782.8 | L41: 751.1 | N41: Average | O41: =AVERAGE(J41:L43) -> 750.11111
A42: Middle | B42: 48.5 | C42: 52 | D42: 53.6 | F42: Minimum | G42: 0 | I42: Middle | J42: 669.1 | K42: 835.6 | L42: 828.4 | N42: Minimum | O42: 0
A43: Bottom | B43: 47.5 | C43: 50.8 | D43: 52.7 | F43: Maximum | G43: 0 | I43: Bottom | J43: 655.9 | K43: 794.9 | L43: 809 | N43: Maximum | O43: 0
F44: Range | G44: 0 | N44: Range | O44: 0
...

Sheet Env 30 Sep
A1: ENV FOR PARTIAL SHADING CONDITIONS
A2: Purpose: Is to see if you get multiple peaks when you have mass partial shading
A3: 20260819-E02 – Temperature Grid (°C) | I3: 20260819-E02 – Irradiance Grid (W/m²)
A4: Position | B4: Left | C4: Centre | D4: Right | F4: Metric | I4: Position | J4: Left | K4: Centre | L4: Right | N4: Metric
A5: Top | B5: 50.8 | C5: 52.8 | D5: 51.6 | F5: Average | G5: =AVERAGE(B5:D7) -> 52.277778 | I5: Top | J5: 679.7 | K5: 832.3 | L5: 685 | N5: Average | O5: =AVERAGE(J5:L7) -> 775.45556
A6: Middle | B6: 50.2 | C6: 53.9 | D6: 52.5 | F6: Minimum | G6: =MIN(B5:D7) -> 50.2 | I6: Middle | J6: 776.2 | K6: 890.5 | L6: 798.6 | N6: Minimum | O6: =MIN(J5:L7) -> 679.7
A7: Bottom | B7: 51.8 | C7: 54.6 | D7: 52.3 | F7: Maximum | G7: =MAX(B5:D7) -> 54.6 | I7: Bottom | J7: 732.5 | K7: 834.3 | L7: 750 | N7: Maximum | O7: =MAX(J5:L7) -> 890.5
F8: Range | G8: =G7-G6 -> 4.4 | N8: Range | O8: =O7-O6 -> 210.8
A9: ENVIRONMENTAL & TEST CONDITIONS: | F9: Std | G9: =_xlfn.STDEV.S(B5:D7) -> 1.3935367 | N9: Uniform(%) | O9: =((MAX(J5:L7)-MIN(J5:L7))/(MAX(J5:L7)+MIN(J5:L7)))*100 -> 13.425041
A10: Lamp Distance (cm): | C10: Inside variac voltage is 220V
A11: Fan Condition: | C11: Off, distance is 60 cm
A12: Window Condition: | C12: Closed / unShielded
A13: Test Purpose / Notes: | C13: BASELINE
A16: 20260819-E02 – Temperature Grid (°C) | I16: 20260819-E02 – Irradiance Grid (W/m²)
A17: Position | B17: Left | C17: Centre | D17: Right | F17: Metric | I17: Position | J17: Left | K17: Centre | L17: Right | N17: Metric
A18: Top | B18: 52.9 | C18: 55 | D18: 54 | F18: Average | G18: =AVERAGE(B18:D20) -> 54.611111 | I18: Top | J18: 698.4 | K18: 817.8 | L18: 694.4 | N18: Average | O18: =AVERAGE(J18:L20) -> 776.91111
A19: Middle | B19: 52.6 | C19: 58 | D19: 55.9 | F19: Minimum | G19: =MIN(B18:D20) -> 50.9 | I19: Middle | J19: 787.4 | K19: 896.6 | L19: 780.1 | N19: Minimum | O19: =MIN(J18:L20) -> 694.4
A20: Bottom | B20: 50.9 | C20: 57.2 | D20: 55 | F20: Maximum | G20: =MAX(B18:D20) -> 58 | I20: Bottom | J20: 744.4 | K20: 828.4 | L20: 744.7 | N20: Maximum | O20: =MAX(J18:L20) -> 896.6
F21: Range | G21: =G20-G19 -> 7.1 | N21: Range | O21: =O20-O19 -> 202.2
A22: ENVIRONMENTAL & TEST CONDITIONS: | F22: Std | G22: =_xlfn.STDEV.S(B18:D20) -> 2.2712576 | N22: Uniform(%) | O22: =((MAX(J18:L20)-MIN(J18:L20))/(MAX(J18:L20)+MIN(J18:L20)))*100 -> 12.708988
A23: Lamp Distance (cm): | C23: Inside variac voltage is 220V | H23: after 5 min the temp of the covered area was = 40
A24: Fan Condition: | C24: Off, distance is 60 cm
A25: Window Condition: | C25: Closed / unShielded
A26: Test Purpose / Notes: | C26: Cover col 3 row (1-5)
A29: 20260819-E02 – Temperature Grid (°C) | I29: 20260819-E02 – Irradiance Grid (W/m²)
A30: Position | B30: Left | C30: Centre | D30: Right | F30: Metric | I30: Position | J30: Left | K30: Centre | L30: Right | N30: Metric
A31: Top | B31: 48 | C31: 55 | D31: 54 | F31: Average | G31: #DIV/0! | I31: Top | J31: 675.3 | K31: 839.6 | L31: 698.2 | N31: Average | O31: #DIV/0!
A32: Middle | B32: 52.5 | C32: 56.8 | D32: 55.2 | F32: Minimum | G32: 0 | I32: Middle | J32: 789.4 | K32: 888.5 | L32: 785.4 | N32: Minimum | O32: 0
A33: Bottom | B33: 53 | C33: 56.2 | D33: 55 | F33: Maximum | G33: 0 | I33: Bottom | J33: 737.8 | K33: 835.6 | L33: 743.8 | N33: Maximum | O33: 0
F34: Range | G34: 0 | N34: Range | O34: 0
A35: ENVIRONMENTAL & TEST CONDITIONS: | F35: Std | G35: #DIV/0! | N35: Uniform(%) | O35: #DIV/0!
A36: Lamp Distance (cm): | C36: Inside variac voltage is 220V
A37: Fan Condition: | C37: Off, distance is 60 cm
A38: Window Condition: | C38: Closed / unShielded
A39: Test Purpose / Notes: | C39: Cover col 2 row (1-5)
A42: 20260819-E02 – Temperature Grid (°C) | I42: 20260819-E02 – Irradiance Grid (W/m²)
A43: Position | B43: Left | C43: Centre | D43: Right | F43: Metric | I43: Position | J43: Left | K43: Centre | L43: Right | N43: Metric
A44: Top | B44: 50 | C44: 51.4 | D44: 53 | F44: Average | G44: #DIV/0! | I44: Top | J44: 705 | K44: 850.2 | L44: 693.6 | N44: Average | O44: #DIV/0!
A45: Middle | B45: 53.2 | C45: 56.7 | D45: 54.6 | F45: Minimum | G45: 0 | I45: Middle | J45: 792 | K45: 904.6 | L45: 787.6 | N45: Minimum | O45: 0
A46: Bottom | B46: 52.4 | C46: 56.2 | D46: 53.6 | F46: Maximum | G46: 0 | I46: Bottom | J46: 751.7 | K46: 851.7 | L46: 764.5 | N46: Maximum | O46: 0
...

Sheet Env 30 Sep 
A1: ENV FOR PARTIAL SHADING CONDITIONS - repeat because some data was missing
A2: Purpose: Is to see if you get multiple peaks when you have mass partial shading
A3: 20260819-E02 – Temperature Grid (°C) | I3: 20260819-E02 – Irradiance Grid (W/m²)
A4: Position | B4: Left | C4: Centre | D4: Right | F4: Metric | I4: Position | J4: Left | K4: Centre | L4: Right | N4: Metric
A5: Top | B5: 49 | C5: 53 | D5: 50.8 | F5: Average | G5: =AVERAGE(B5:D7) -> 51.333333 | I5: Top | J5: 685.6 | K5: 823.1 | L5: 679.7 | N5: Average | O5: =AVERAGE(J5:L7) -> 770.3
A6: Middle | B6: 50.3 | C6: 53.9 | D6: 52.5 | F6: Minimum | G6: =MIN(B5:D7) -> 48.9 | I6: Middle | J6: 779.5 | K6: 893.1 | L6: 777 | N6: Minimum | O6: =MIN(J5:L7) -> 679.7
A7: Bottom | B7: 48.9 | C7: 53.4 | D7: 50.2 | F7: Maximum | G7: =MAX(B5:D7) -> 53.9 | I7: Bottom | J7: 744.4 | K7: 821.1 | L7: 729.2 | N7: Maximum | O7: =MAX(J5:L7) -> 893.1
F8: Range | G8: =G7-G6 -> 5 | N8: Range | O8: =O7-O6 -> 213.4
A9: ENVIRONMENTAL & TEST CONDITIONS: | F9: Std | G9: =_xlfn.STDEV.S(B5:D7) -> 1.9039433 | N9: Uniform(%) | O9: =((MAX(J5:L7)-MIN(J5:L7))/(MAX(J5:L7)+MIN(J5:L7)))*100 -> 13.568159
A10: Lamp Distance (cm): | C10: Inside variac voltage is 220V
A11: Fan Condition: | C11: Off, distance is 60 cm
A12: Window Condition: | C12: Closed / unShielded
A13: Test Purpose / Notes: | C13: BASELINE
A15: 20260819-E02 – Temperature Grid (°C) | I15: 20260819-E02 – Irradiance Grid (W/m²)
A16: Position | B16: Left | C16: Centre | D16: Right | F16: Metric | I16: Position | J16: Left | K16: Centre | L16: Right | N16: Metric
A17: Top | B17: 48.9 | C17: 53.3 | D17: 50.4 | F17: Average | G17: =AVERAGE(B17:D19) -> 51.855556 | I17: Top | J17: 710.1 | K17: 846.2 | L17: 698.2 | N17: Average | O17: =AVERAGE(J17:L19) -> 774.37778
A18: Middle | B18: 51.1 | C18: 55 | D18: 52 | F18: Minimum | G18: =MIN(B17:D19) -> 48.9 | I18: Middle | J18: 765.1 | K18: 890 | L18: 780.8 | N18: Minimum | O18: =MIN(J17:L19) -> 698.2
A19: Bottom | B19: 50.9 | C19: 54 | D19: 51.1 | F19: Maximum | G19: =MAX(B17:D19) -> 55 | I19: Bottom | J19: 731.9 | K19: 821.1 | L19: 726 | N19: Maximum | O19: =MAX(J17:L19) -> 890
F20: Range | G20: =G19-G18 -> 6.1 | N20: Range | O20: =O19-O18 -> 191.8
A21: ENVIRONMENTAL & TEST CONDITIONS: | F21: Std | G21: =_xlfn.STDEV.S(B17:D19) -> 1.9203588 | N21: Uniform(%) | O21: =((MAX(J17:L19)-MIN(J17:L19))/(MAX(J17:L19)+MIN(J17:L19)))*100 -> 12.076565
A22: Lamp Distance (cm): | C22: Inside variac voltage is 220V
A23: Fan Condition: | C23: Off, distance is 60 cm
A24: Window Condition: | C24: Closed / unShielded
A25: Test Purpose / Notes: | C25: col3 row 1-5
A27: 20260819-E02 – Temperature Grid (°C) | I27: 20260819-E02 – Irradiance Grid (W/m²)
A28: Position | B28: Left | C28: Centre | D28: Right | F28: Metric | I28: Position | J28: Left | K28: Centre | L28: Right | N28: Metric
A29: Top | B29: 50.2 | C29: 52.8 | D29: 50.8 | F29: Average | G29: =AVERAGE(B29:D31) -> 52.077778 | I29: Top | J29: 719.3 | K29: 872.9 | L29: 714.9 | N29: Average | O29: =AVERAGE(J29:L31) -> 791.63333
A30: Middle | B30: 51.5 | C30: 54.5 | D30: 53.2 | F30: Minimum | G30: =MIN(B29:D31) -> 49.8 | I30: Middle | J30: 764.5 | K30: 914 | L30: 806.6 | N30: Minimum | O30: =MIN(J29:L31) -> 714.9
A31: Bottom | B31: 49.8 | C31: 53.8 | D31: 52.1 | F31: Maximum | G31: =MAX(B29:D31) -> 54.5 | I31: Bottom | J31: 715.4 | K31: 850 | L31: 767.1 | N31: Maximum | O31: =MAX(J29:L31) -> 914
F32: Range | G32: =G31-G30 -> 4.7 | N32: Range | O32: =O31-O30 -> 199.1
A33: ENVIRONMENTAL & TEST CONDITIONS: | F33: Std | G33: =_xlfn.STDEV.S(B29:D31) -> 1.6315466 | N33: Uniform(%) | O33: =((MAX(J29:L31)-MIN(J29:L31))/(MAX(J29:L31)+MIN(J29:L31)))*100 -> 12.222973
A34: Lamp Distance (cm): | C34: Inside variac voltage is 220V
A35: Fan Condition: | C35: Off, distance is 60 cm
A36: Window Condition: | C36: Closed / unShielded
A37: Test Purpose / Notes: | C37: col3 row 11 moving cloud

Sheet Env 1 October 
A1: Investigating bypass diode and serverity of the shading
A5: 20260819-E02 – Temperature Grid (°C) | I5: 20260819-E02 – Irradiance Grid (W/m²)
A6: Position | B6: Left | C6: Centre | D6: Right | F6: Metric | I6: Position | J6: Left | K6: Centre | L6: Right | N6: Metric
A7: Top | B7: 50 | C7: 54.8 | D7: 52 | F7: Average | G7: =AVERAGE(B7:D9) -> 53.244444 | I7: Top | J7: 690.3 | K7: 842.9 | L7: 673.1 | N7: Average | O7: =AVERAGE(J7:L9) -> 775.8
A8: Middle | B8: 53.9 | C8: 55 | D8: 55 | F8: Minimum | G8: =MIN(B7:D9) -> 50 | I8: Middle | J8: 762.3 | K8: 896.4 | L8: 825.7 | N8: Minimum | O8: =MIN(J7:L9) -> 673.1
A9: Bottom | B9: 51 | C9: 53 | D9: 54.5 | F9: Maximum | G9: =MAX(B7:D9) -> 55 | I9: Bottom | J9: 712.7 | K9: 819.8 | L9: 759 | N9: Maximum | O9: =MAX(J7:L9) -> 896.4
F10: Range | G10: =G9-G8 -> 5 | N10: Range | O10: =O9-O8 -> 223.3
A11: ENVIRONMENTAL & TEST CONDITIONS: | F11: Std | G11: =_xlfn.STDEV.S(B7:D9) -> 1.8628682 | N11: Uniform(%) | O11: =((MAX(J7:L9)-MIN(J7:L9))/(MAX(J7:L9)+MIN(J7:L9)))*100 -> 14.227461
A12: Lamp Distance (cm): | C12: Inside variac voltage is 220V
A13: Fan Condition: | C13: Off, distance is 60 cm
A14: Window Condition: | C14: Closed / unShielded
A15: Test Purpose / Notes: | C15: baseline
A18: 20260819-E02 – Temperature Grid (°C) | I18: 20260819-E02 – Irradiance Grid (W/m²)
A19: Position | B19: Left | C19: Centre | D19: Right | F19: Metric | I19: Position | J19: Left | K19: Centre | L19: Right | N19: Metric
